Workbook

Sheet README
A1: Suivi patrimonial familial (KISS) — Mode d’emploi
A3: Objectif : saisir une photo (snapshot) du patrimoine à fréquence mensuelle ou trimestrielle, et obtenir automatiquement une synthèse.
A5: 1) Onglet POSITIONS :
A6: Une ligne = une enveloppe à une date (valorisation + dette éventuelle).
A7: Pour une date donnée, renseignez toutes les enveloppes que vous voulez inclure dans le total.
A9: 2) Onglet FLUX (optionnel) :
A10: Ne saisis que des flux EXTERNES (apports / sorties du patrimoine global).
A11: Ne saisis pas les virements internes (compte courant -> livret, arbitrages, etc.).
A12: Convention signe : + = augmente le patrimoine (apport), - = diminue (sortie).
A14: 3) Onglet SYNTHESE :
A15: Totaux par personne et famille à la dernière date saisie.
A16: Historique : renseignez une liste de dates (colonne A), la courbe se met à jour automatiquement.

Sheet Listes
A1: Propriétaires | B1: Catégories | C1: Enveloppes | D1: Types de flux | E1: Liquidité (délai) | F1: Friction | H1: Enveloppes | I1: Liquidité | J1: Friction | L1: Catégories | M1: % Mobilisable
A2: Paul | B2: Cash & dépôts | C2: Compte courant | D2: Versement | E2: J0–J1 | F2: Aucune | H2: =C2 -> Compte courant | I2: J0–J1 | J2: Aucune | L2: =B2 -> Cash & dépôts | M2: 1
A3: Claire | B3: Monétaire | C3: Livret A | D3: Retrait | E3: J2–J7 | F3: Fiscale | H3: =C3 -> Livret A | I3: J0–J1 | J3: Aucune | L3: =B3 -> Monétaire | M3: 0.95
A4: Léo | B4: Obligations | C4: LDDS | D4: Dividende/Intérêt | E4: J8–J30 | F4: Frais | H4: =C4 -> LDDS | I4: J0–J1 | J4: Aucune | L4: =B4 -> Obligations | M4: 0.95
A5: Zoé | B5: Actions | C5: Livret Bourso+ | D5: Frais | E5: 30J+ | F5: Décote probable | H5: =C5 -> Livret Bourso+ | I5: J0–J1 | J5: Aucune | L5: =B5 -> Actions | M5: 0.9
B6: Immobilier | C6: PEL/CEL | D6: Autre | E6: Bloqué | F6: Mixte | H6: =C6 -> PEL/CEL | I6: J8–J30 | J6: Frais | L6: =B6 -> Immobilier | M6: 0
B7: SCPI | C7: PEA | H7: =C7 -> PEA | I7: J2–J7 | J7: Fiscale | L7: =B7 -> SCPI | M7: 0
B8: Fond Euro | C8: CTO | H8: =C8 -> CTO | I8: J2–J7 | J8: Fiscale | L8: =B8 -> Fond Euro | M8: 0.95
B9: Produits Structurés | C9: Assurance-vie | H9: =C9 -> Assurance-vie | I9: J8–J30 | J9: Mixte | L9: =B9 -> Produits Structurés | M9: 0
B10: Crypto | C10: PER | H10: =C10 -> PER | I10: Bloqué | J10: Fiscale | L10: =B10 -> Crypto | M10: 0.9
B11: Objets de valeur | C11: Crypto | H11: =C11 -> Crypto | I11: J0–J1 | J11: Décote probable | L11: =B11 -> Objets de valeur | M11: 0
B12: Autre | C12: Immobilier | H12: =C12 -> Immobilier | I12: 30J+ | J12: Mixte | L12: =B12 -> Autre | M12: 0.8
C13: SCI | H13: =C13 -> SCI | I13: 30J+ | J13: Mixte
C14: Dette | H14: =C14 -> Dette | I14: Bloqué | J14: Aucune
C15: Autre | H15: =C15 -> Autre | I15: 30J+ | J15: Mixte

Sheet Positions
A1: Date | B1: Propriétaire | C1: Catégorie | D1: Enveloppe | E1: Établissement | F1: Valeur (€) | G1: Dette restante (€) | H1: Valeur nette (€) | I1: Notes | J1: Entité (si indivision/SCI) | K1: % propriété (0-1) | L1: % dette (0-1) | M1: Mode (auto) | N1: Actif brut attribué (€) | O1: Dette attribuée (€) | P1: Valeur nette attribuée (€) | Q1: Liquidité (délai) | R1: Mobilisable (%) | S1: Friction | T1: Valeur mobilisable (€)
A2: 46069 | B2: Paul | C2: Cash & dépôts
A3: 46069 | B3: Paul | C3: Cash & dépôts
A4: 46069 | B4: Paul | C4: Cash & dépôts
A5: 46069 | B5: Paul | C5: Actions
A6: 46069 | B6: Paul | C6: Fond Euro
A7: 46069 | B7: Paul | C7: Monétaire
A8: 46069 | B8: Paul | C8: Actions
A9: 46069 | B9: Paul | C9: Actions
A10: 46069 | B10: Paul | C10: Actions
A11: 46069 | B11: Paul | C11: Fond Euro
A12: 46069 | B12: Paul | C12: Crypto
A13: 46069 | B13: Paul | C13: Produits Structurés
... A120: 46097 | B120: Paul | C120: Autre

Sheet Flux
A1: Date | B1: Propriétaire | C1: Enveloppe | D1: Type | E1: Montant (€) (signé) | F1: Notes

Sheet Entites
A1: Entité | B1: Type | C1: Mode de valorisation | D1: Actif brut (€) | E1: Dette (€) | F1: Actif net entité (€) | G1: Commentaire

Sheet Synthese
A1: Note : pour indivision/SCI, renseigne 'Entité' et '% détention' dans Positions. Les totaux utilisent 'Valeur attribuée'.
A3: Dernière date saisie : | B3: =MAX(Positions!A:A) -> 46097
A5: Totaux à la dernière date | F5: Répartition par catégorie (net)
A6: Propriétaire | B6: Actifs (€) | C6: Dettes (€) | D6: Net (€) | F6: Catégorie | G6: Net (€) | H6: {=TRANSPOSE(A7:A10)} -> Paul | I6: Claire | J6: Léo | K6: Zoé
A7: =Listes!A2 -> Paul | B7: =IF($B$3="","",SUMIFS(Positions!$N$2:$N$300,Positions!$A$2:$A$300,$B$3,Positions!$B$2:$B$300,$A7)) -> 0 | C7: =IF($B$3="","",SUMIFS(Positions!$O$2:$O$300,Positions!$A$2:$A$300,$B$3,Positions!$B$2:$B$300,$A7)) -> 0 | D7: =IF($B$3="","",SUMIFS(Positions!$P$2:$P$300,Positions!$A$2:$A$300,$B$3,Positions!$B$2:$B$300,$A7)) -> 0 | F7: =Listes!B2 -> Cash & dépôts | G7: =IF($B$3="","",SUMIFS(Positions!$P:$P,Positions!$A:$A,$B$3,Positions!$C:$C,$F7)) -> 0 | H7: =IF($B$3="","",SUMIFS(Positions!$P:$P,Positions!$A:$A,$B$3,Positions!$B:$B,H$6,Positions!$C:$C,$F7)) -> 0 | I7: =IF($B$3="","",SUMIFS(Positions!$P:$P,Positions!$A:$A,$B$3,Positions!$B:$B,I$6,Positions!$C:$C,$F7)) -> 0 | J7: =IF($B$3="","",SUMIFS(Positions!$P:$P,Positions!$A:$A,$B$3,Positions!$B:$B,J$6,Positions!$C:$C,$F7)) -> 0 | K7: =IF($B$3="","",SUMIFS(Positions!$P:$P,Positions!$A:$A,$B$3,Positions!$B:$B,K$6,Positions!$C:$C,$F7)) -> 0
A8: =Listes!A3 -> Claire | B8: =IF($B$3="","",SUMIFS(Positions!$N$2:$N$300,Positions!$A$2:$A$300,$B$3,Positions!$B$2:$B$300,$A8)) -> 0 | C8: =IF($B$3="","",SUMIFS(Positions!$O$2:$O$300,Positions!$A$2:$A$300,$B$3,Positions!$B$2:$B$300,$A8)) -> 0 | D8: =IF($B$3="","",SUMIFS(Positions!$P$2:$P$300,Positions!$A$2:$A$300,$B$3,Positions!$B$2:$B$300,$A8)) -> 0 | F8: =Listes!B3 -> Monétaire | G8: =IF($B$3="","",SUMIFS(Positions!$P:$P,Positions!$A:$A,$B$3,Positions!$C:$C,$F8)) -> 0 | H8: =IF($B$3="","",SUMIFS(Positions!$P:$P,Positions!$A:$A,$B$3,Positions!$B:$B,H$6,Positions!$C:$C,$F8)) -> 0 | I8: =IF($B$3="","",SUMIFS(Positions!$P:$P,Positions!$A:$A,$B$3,Positions!$B:$B,I$6,Positions!$C:$C,$F8)) -> 0 | J8: =IF($B$3="","",SUMIFS(Positions!$P:$P,Positions!$A:$A,$B$3,Positions!$B:$B,J$6,Positions!$C:$C,$F8)) -> 0 | K8: =IF($B$3="","",SUMIFS(Positions!$P:$P,Positions!$A:$A,$B$3,Positions!$B:$B,K$6,Positions!$C:$C,$F8)) -> 0
A9: =Listes!A4 -> Léo | B9: =IF($B$3="","",SUMIFS(Positions!$N$2:$N$300,Positions!$A$2:$A$300,$B$3,Positions!$B$2:$B$300,$A9)) -> 0 | C9: =IF($B$3="","",SUMIFS(Positions!$O$2:$O$300,Positions!$A$2:$A$300,$B$3,Positions!$B$2:$B$300,$A9)) -> 0 | D9: =IF($B$3="","",SUMIFS(Positions!$P$2:$P$300,Positions!$A$2:$A$300,$B$3,Positions!$B$2:$B$300,$A9)) -> 0 | F9: =Listes!B4 -> Obligations | G9: =IF($B$3="","",SUMIFS(Positions!$P:$P,Positions!$A:$A,$B$3,Positions!$C:$C,$F9)) -> 0 | H9: =IF($B$3="","",SUMIFS(Positions!$P:$P,Positions!$A:$A,$B$3,Positions!$B:$B,H$6,Positions!$C:$C,$F9)) -> 0 | I9: =IF($B$3="","",SUMIFS(Positions!$P:$P,Positions!$A:$A,$B$3,Positions!$B:$B,I$6,Positions!$C:$C,$F9)) -> 0 | J9: =IF($B$3="","",SUMIFS(Positions!$P:$P,Positions!$A:$A,$B$3,Positions!$B:$B,J$6,Positions!$C:$C,$F9)) -> 0 | K9: =IF($B$3="","",SUMIFS(Positions!$P:$P,Positions!$A:$A,$B$3,Positions!$B:$B,K$6,Positions!$C:$C,$F9)) -> 0
A10: =Listes!A5 -> Zoé | B10: =IF($B$3="","",SUMIFS(Positions!$N$2:$N$300,Positions!$A$2:$A$300,$B$3,Positions!$B$2:$B$300,$A10)) -> 0 | C10: =IF($B$3="","",SUMIFS(Positions!$O$2:$O$300,Positions!$A$2:$A$300,$B$3,Positions!$B$2:$B$300,$A10)) -> 0 | D10: =IF($B$3="","",SUMIFS(Positions!$P$2:$P$300,Positions!$A$2:$A$300,$B$3,Positions!$B$2:$B$300,$A10)) -> 0 | F10: =Listes!B5 -> Actions | G10: =IF($B$3="","",SUMIFS(Positions!$P:$P,Positions!$A:$A,$B$3,Positions!$C:$C,$F10)) -> 0 | H10: =IF($B$3="","",SUMIFS(Positions!$P:$P,Positions!$A:$A,$B$3,Positions!$B:$B,H$6,Positions!$C:$C,$F10)) -> 0 | I10: =IF($B$3="","",SUMIFS(Positions!$P:$P,Positions!$A:$A,$B$3,Positions!$B:$B,I$6,Positions!$C:$C,$F10)) -> 0 | J10: =IF($B$3="","",SUMIFS(Positions!$P:$P,Positions!$A:$A,$B$3,Positions!$B:$B,J$6,Positions!$C:$C,$F10)) -> 0 | K10: =IF($B$3="","",SUMIFS(Positions!$P:$P,Positions!$A:$A,$B$3,Positions!$B:$B,K$6,Positions!$C:$C,$F10)) -> 0
A11: TOTAL FAMILLE | B11: =IF($B$3="","",SUM(B7:B10)) -> 0 | C11: =IF($B$3="","",SUM(C7:C10)) -> 0 | D11: =IF($B$3="","",SUM(D7:D10)) -> 0 | F11: =Listes!B6 -> Immobilier | G11: =IF($B$3="","",SUMIFS(Positions!$P:$P,Positions!$A:$A,$B$3,Positions!$C:$C,$F11)) -> 0 | H11: =IF($B$3="","",SUMIFS(Positions!$P:$P,Positions!$A:$A,$B$3,Positions!$B:$B,H$6,Positions!$C:$C,$F11)) -> 0 | I11: =IF($B$3="","",SUMIFS(Positions!$P:$P,Positions!$A:$A,$B$3,Positions!$B:$B,I$6,Positions!$C:$C,$F11)) -> 0 | J11: =IF($B$3="","",SUMIFS(Positions!$P:$P,Positions!$A:$A,$B$3,Positions!$B:$B,J$6,Positions!$C:$C,$F11)) -> 0 | K11: =IF($B$3="","",SUMIFS(Positions!$P:$P,Positions!$A:$A,$B$3,Positions!$B:$B,K$6,Positions!$C:$C,$F11)) -> 0
F12: =Listes!B7 -> SCPI | G12: =IF($B$3="","",SUMIFS(Positions!$P:$P,Positions!$A:$A,$B$3,Positions!$C:$C,$F12)) -> 0 | H12: =IF($B$3="","",SUMIFS(Positions!$P:$P,Positions!$A:$A,$B$3,Positions!$B:$B,H$6,Positions!$C:$C,$F12)) -> 0 | I12: =IF($B$3="","",SUMIFS(Positions!$P:$P,Positions!$A:$A,$B$3,Positions!$B:$B,I$6,Positions!$C:$C,$F12)) -> 0 | J12: =IF($B$3="","",SUMIFS(Positions!$P:$P,Positions!$A:$A,$B$3,Positions!$B:$B,J$6,Positions!$C:$C,$F12)) -> 0 | K12: =IF($B$3="","",SUMIFS(Positions!$P:$P,Positions!$A:$A,$B$3,Positions!$B:$B,K$6,Positions!$C:$C,$F12)) -> 0
F13: =Listes!B8 -> Fond Euro | G13: =IF($B$3="","",SUMIFS(Positions!$P:$P,Positions!$A:$A,$B$3,Positions!$C:$C,$F13)) -> 0 | H13: =IF($B$3="","",SUMIFS(Positions!$P:$P,Positions!$A:$A,$B$3,Positions!$B:$B,H$6,Positions!$C:$C,$F13)) -> 0 | I13: =IF($B$3="","",SUMIFS(Positions!$P:$P,Positions!$A:$A,$B$3,Positions!$B:$B,I$6,Positions!$C:$C,$F13)) -> 0 | J13: =IF($B$3="","",SUMIFS(Positions!$P:$P,Positions!$A:$A,$B$3,Positions!$B:$B,J$6,Positions!$C:$C,$F13)) -> 0 | K13: =IF($B$3="","",SUMIFS(Positions!$P:$P,Positions!$A:$A,$B$3,Positions!$B:$B,K$6,Positions!$C:$C,$F13)) -> 0
A14: Variation & flux (lecture “rentabilité” simple) | F14: =Listes!B9 -> Produits Structurés | G14: =IF($B$3="","",SUMIFS(Positions!$P:$P,Positions!$A:$A,$B$3,Positions!$C:$C,$F14)) -> 0 | H14: =IF($B$3="","",SUMIFS(Positions!$P:$P,Positions!$A:$A,$B$3,Positions!$B:$B,H$6,Positions!$C:$C,$F14)) -> 0 | I14: =IF($B$3="","",SUMIFS(Positions!$P:$P,Positions!$A:$A,$B$3,Positions!$B:$B,I$6,Positions!$C:$C,$F14)) -> 0 | J14: =IF($B$3="","",SUMIFS(Positions!$P:$P,Positions!$A:$A,$B$3,Positions!$B:$B,J$6,Positions!$C:$C,$F14)) -> 0 | K14: =IF($B$3="","",SUMIFS(Positions!$P:$P,Positions!$A:$A,$B$3,Positions!$B:$B,K$6,Positions!$C:$C,$F14)) -> 0
A15: Date début | B15: Date fin | C15: Info | F15: =Listes!B10 -> Crypto | G15: =IF($B$3="","",SUMIFS(Positions!$P:$P,Positions!$A:$A,$B$3,Positions!$C:$C,$F15)) -> 0 | H15: =IF($B$3="","",SUMIFS(Positions!$P:$P,Positions!$A:$A,$B$3,Positions!$B:$B,H$6,Positions!$C:$C,$F15)) -> 0 | I15: =IF($B$3="","",SUMIFS(Positions!$P:$P,Positions!$A:$A,$B$3,Positions!$B:$B,I$6,Positions!$C:$C,$F15)) -> 0 | J15: =IF($B$3="","",SUMIFS(Positions!$P:$P,Positions!$A:$A,$B$3,Positions!$B:$B,J$6,Positions!$C:$C,$F15)) -> 0 | K15: =IF($B$3="","",SUMIFS(Positions!$P:$P,Positions!$A:$A,$B$3,Positions!$B:$B,K$6,Positions!$C:$C,$F15)) -> 0
A16: 46069 | B16: =$B$3 -> 46097 | C16: Modifiez F20 si besoin. | F16: =Listes!B11 -> Objets de valeur | G16: =IF($B$3="","",SUMIFS(Positions!$P:$P,Positions!$A:$A,$B$3,Positions!$C:$C,$F16)) -> 0 | H16: =IF($B$3="","",SUMIFS(Positions!$P:$P,Positions!$A:$A,$B$3,Positions!$B:$B,H$6,Positions!$C:$C,$F16)) -> 0 | I16: =IF($B$3="","",SUMIFS(Positions!$P:$P,Positions!$A:$A,$B$3,Positions!$B:$B,I$6,Positions!$C:$C,$F16)) -> 0 | J16: =IF($B$3="","",SUMIFS(Positions!$P:$P,Positions!$A:$A,$B$3,Positions!$B:$B,J$6,Positions!$C:$C,$F16)) -> 0 | K16: =IF($B$3="","",SUMIFS(Positions!$P:$P,Positions!$A:$A,$B$3,Positions!$B:$B,K$6,Positions!$C:$C,$F16)) -> 0
F17: =Listes!B12 -> Autre | G17: =IF($B$3="","",SUMIFS(Positions!$P:$P,Positions!$A:$A,$B$3,Positions!$C:$C,$F17)) -> 0 | H17: =IF($B$3="","",SUMIFS(Positions!$P:$P,Positions!$A:$A,$B$3,Positions!$B:$B,H$6,Positions!$C:$C,$F17)) -> 0 | I17: =IF($B$3="","",SUMIFS(Positions!$P:$P,Positions!$A:$A,$B$3,Positions!$B:$B,I$6,Positions!$C:$C,$F17)) -> 0 | J17: =IF($B$3="","",SUMIFS(Positions!$P:$P,Positions!$A:$A,$B$3,Positions!$B:$B,J$6,Positions!$C:$C,$F17)) -> 0 | K17: =IF($B$3="","",SUMIFS(Positions!$P:$P,Positions!$A:$A,$B$3,Positions!$B:$B,K$6,Positions!$C:$C,$F17)) -> 0
A18: Net début (€) | B18: =IF($A$16="","",SUMIFS(Positions!$P$2:$P$300,Positions!$A$2:$A$300,$A$16)) -> 0 | C18: Somme des valeurs nettes à la date début. | F18: Total | G18: =IF(SUM(G7:G17)=D11,SUM(G7:G17),"Erreur") -> 0 | H18: =IF(SUM(H7:H17)=D7,SUM(H7:H17),"Erreur") -> 0 | I18: =IF(SUM(I7:I17)=D8,SUM(I7:I17),"Erreur") -> 0 | J18: =IF(SUM(J7:J17)=D9,SUM(J7:J17),"Erreur") -> 0 | K18: =IF(SUM(K7:K17)=D10,SUM(K7:K17),"Erreur") -> 0
A19: Net fin (€) | B19: =IF($B$16="","",SUMIFS(Positions!$P$2:$P$300,Positions!$A$2:$A$300,$B$16)) -> 0 | C19: Somme des valeurs nettes à la date fin.
A20: Flux net (€) | B20: =IF(OR($A$16="",$B$16=""),"",SUMIFS(Flux!$E$2:$E$301,Flux!$A$2:$A$301,">="&$A$16,Flux!$A$2:$A$301,"<="&$B$16)) -> 0 | C20: Somme des flux signés sur la période. | F20: Répartition par enveloppe (net)
A21: Variation nette (€) | B21: =IF(OR($B$18="",$B$19=""),"",$B$19-$B$18) -> 0 | C21: Net fin - net début. | F21: Enveloppe | G21: Net (€) | H21: {=TRANSPOSE(Listes!A2:A5)} -> Paul | I21: Claire | J21: Léo | K21: Zoé
A22: Gain/perte hors flux (€) | B22: =IF(OR($B$21="",$B$20=""),"",$B$21-$B$20) -> 0 | C22: Variation - flux (approx perf). | F22: =Listes!C2 -> Compte courant | G22: =IF($B$3="","",SUMIFS(Positions!$P:$P,Positions!$A:$A,$B$3,Positions!$D:$D,$F22)) -> 0 | H22: =IF($B$3="","",SUMIFS(Positions!$P:$P,Positions!$A:$A,$B$3,Positions!$B:$B,H$21,Positions!$D:$D,$F22)) -> 0 | I22: =IF($B$3="","",SUMIFS(Positions!$P:$P,Positions!$A:$A,$B$3,Positions!$B:$B,I$21,Positions!$D:$D,$F22)) -> 0 | J22: =IF($B$3="","",SUMIFS(Positions!$P:$P,Positions!$A:$A,$B$3,Positions!$B:$B,J$21,Positions!$D:$D,$F22)) -> 0 | K22: =IF($B$3="","",SUMIFS(Positions!$P:$P,Positions!$A:$A,$B$3,Positions!$B:$B,K$21,Positions!$D:$D,$F22)) -> 0
F23: =Listes!C3 -> Livret A | G23: =IF($B$3="","",SUMIFS(Positions!$P:$P,Positions!$A:$A,$B$3,Positions!$D:$D,$F23)) -> 0 | H23: =IF($B$3="","",SUMIFS(Positions!$P:$P,Positions!$A:$A,$B$3,Positions!$B:$B,H$21,Positions!$D:$D,$F23)) -> 0 | I23: =IF($B$3="","",SUMIFS(Positions!$P:$P,Positions!$A:$A,$B$3,Positions!$B:$B,I$21,Positions!$D:$D,$F23)) -> 0 | J23: =IF($B$3="","",SUMIFS(Positions!$P:$P,Positions!$A:$A,$B$3,Positions!$B:$B,J$21,Positions!$D:$D,$F23)) -> 0 | K23: =IF($B$3="","",SUMIFS(Positions!$P:$P,Positions!$A:$A,$B$3,Positions!$B:$B,K$21,Positions!$D:$D,$F23)) -> 0
F24: =Listes!C4 -> LDDS | G24: =IF($B$3="","",SUMIFS(Positions!$P:$P,Positions!$A:$A,$B$3,Positions!$D:$D,$F24)) -> 0 | H24: =IF($B$3="","",SUMIFS(Positions!$P:$P,Positions!$A:$A,$B$3,Positions!$B:$B,H$21,Positions!$D:$D,$F24)) -> 0 | I24: =IF($B$3="","",SUMIFS(Positions!$P:$P,Positions!$A:$A,$B$3,Positions!$B:$B,I$21,Positions!$D:$D,$F24)) -> 0 | J24: =IF($B$3="","",SUMIFS(Positions!$P:$P,Positions!$A:$A,$B$3,Positions!$B:$B,J$21,Positions!$D:$D,$F24)) -> 0 | K24: =IF($B$3="","",SUMIFS(Positions!$P:$P,Positions!$A:$A,$B$3,Positions!$B:$B,K$21,Positions!$D:$D,$F24)) -> 0
A25: Historique (renseignez les dates en colonne A) | F25: =Listes!C5 -> Livret Bourso+ | G25: =IF($B$3="","",SUMIFS(Positions!$P:$P,Positions!$A:$A,$B$3,Positions!$D:$D,$F25)) -> 0 | H25: =IF($B$3="","",SUMIFS(Positions!$P:$P,Positions!$A:$A,$B$3,Positions!$B:$B,H$21,Positions!$D:$D,$F25)) -> 0 | I25: =IF($B$3="","",SUMIFS(Positions!$P:$P,Positions!$A:$A,$B$3,Positions!$B:$B,I$21,Positions!$D:$D,$F25)) -> 0 | J25: =IF($B$3="","",SUMIFS(Positions!$P:$P,Positions!$A:$A,$B$3,Positions!$B:$B,J$21,Positions!$D:$D,$F25)) -> 0 | K25: =IF($B$3="","",SUMIFS(Positions!$P:$P,Positions!$A:$A,$B$3,Positions!$B:$B,K$21,Positions!$D:$D,$F25)) -> 0
A26: Date | B26: Net famille (€) | C26: Δ période (€) | D26: % Δ (approx.) | F26: =Listes!C6 -> PEL/CEL | G26: =IF($B$3="","",SUMIFS(Positions!$P:$P,Positions!$A:$A,$B$3,Positions!$D:$D,$F26)) -> 0 | H26: =IF($B$3="","",SUMIFS(Positions!$P:$P,Positions!$A:$A,$B$3,Positions!$B:$B,H$21,Positions!$D:$D,$F26)) -> 0 | I26: =IF($B$3="","",SUMIFS(Positions!$P:$P,Positions!$A:$A,$B$3,Positions!$B:$B,I$21,Positions!$D:$D,$F26)) -> 0 | J26: =IF($B$3="","",SUMIFS(Positions!$P:$P,Positions!$A:$A,$B$3,Positions!$B:$B,J$21,Positions!$D:$D,$F26)) -> 0 | K26: =IF($B$3="","",SUMIFS(Positions!$P:$P,Positions!$A:$A,$B$3,Positions!$B:$B,K$21,Positions!$D:$D,$F26)) -> 0
A27: 46069 | B27: =IF($A27="","",SUMIFS(Positions!$P$2:$P$300,Positions!$A$2:$A$300,$A27)) -> 0 | F27: =Listes!C7 -> PEA | G27: =IF($B$3="","",SUMIFS(Positions!$P:$P,Positions!$A:$A,$B$3,Positions!$D:$D,$F27)) -> 0 | H27: =IF($B$3="","",SUMIFS(Positions!$P:$P,Positions!$A:$A,$B$3,Positions!$B:$B,H$21,Positions!$D:$D,$F27)) -> 0 | I27: =IF($B$3="","",SUMIFS(Positions!$P:$P,Positions!$A:$A,$B$3,Positions!$B:$B,I$21,Positions!$D:$D,$F27)) -> 0 | J27: =IF($B$3="","",SUMIFS(Positions!$P:$P,Positions!$A:$A,$B$3,Positions!$B:$B,J$21,Positions!$D:$D,$F27)) -> 0 | K27: =IF($B$3="","",SUMIFS(Positions!$P:$P,Positions!$A:$A,$B$3,Positions!$B:$B,K$21,Positions!$D:$D,$F27)) -> 0
A28: 46070 | B28: =IF($A28="","",SUMIFS(Positions!$P$2:$P$300,Positions!$A$2:$A$300,$A28)) -> 0 | C28: =IF(OR($A28="",$A27=""),"",$B28-$B27) -> 0 | D28: =IF(OR($A28="",$A27="",$B27=0),"",$C28/$B27) | F28: =Listes!C8 -> CTO | G28: =IF($B$3="","",SUMIFS(Positions!$P:$P,Positions!$A:$A,$B$3,Positions!$D:$D,$F28)) -> 0 | H28: =IF($B$3="","",SUMIFS(Positions!$P:$P,Positions!$A:$A,$B$3,Positions!$B:$B,H$21,Positions!$D:$D,$F28)) -> 0 | I28: =IF($B$3="","",SUMIFS(Positions!$P:$P,Positions!$A:$A,$B$3,Positions!$B:$B,I$21,Positions!$D:$D,$F28)) -> 0 | J28: =IF($B$3="","",SUMIFS(Positions!$P:$P,Positions!$A:$A,$B$3,Positions!$B:$B,J$21,Positions!$D:$D,$F28)) -> 0 | K28: =IF($B$3="","",SUMIFS(Positions!$P:$P,Positions!$A:$A,$B$3,Positions!$B:$B,K$21,Positions!$D:$D,$F28)) -> 0
A29: 46084 | B29: =IF($A29="","",SUMIFS(Positions!$P$2:$P$300,Positions!$A$2:$A$300,$A29)) -> 0 | C29: =IF(OR($A29="",$A28=""),"",$B29-$B28) -> 0 | D29: =IF(OR($A29="",$A28="",$B28=0),"",$C29/$B28) | F29: =Listes!C9 -> Assurance-vie | G29: =IF($B$3="","",SUMIFS(Positions!$P:$P,Positions!$A:$A,$B$3,Positions!$D:$D,$F29)) -> 0 | H29: =IF($B$3="","",SUMIFS(Positions!$P:$P,Positions!$A:$A,$B$3,Positions!$B:$B,H$21,Positions!$D:$D,$F29)) -> 0 | I29: =IF($B$3="","",SUMIFS(Positions!$P:$P,Positions!$A:$A,$B$3,Positions!$B:$B,I$21,Positions!$D:$D,$F29)) -> 0 | J29: =IF($B$3="","",SUMIFS(Positions!$P:$P,Positions!$A:$A,$B$3,Positions!$B:$B,J$21,Positions!$D:$D,$F29)) -> 0 | K29: =IF($B$3="","",SUMIFS(Positions!$P:$P,Positions!$A:$A,$B$3,Positions!$B:$B,K$21,Positions!$D:$D,$F29)) -> 0
A30: 46097 | B30: =IF($A30="","",SUMIFS(Positions!$P$2:$P$300,Positions!$A$2:$A$300,$A30)) -> 0 | C30: =IF(OR($A30="",$A29=""),"",$B30-$B29) -> 0 | D30: =IF(OR($A30="",$A29="",$B29=0),"",$C30/$B29) | F30: =Listes!C10 -> PER | G30: =IF($B$3="","",SUMIFS(Positions!$P:$P,Positions!$A:$A,$B$3,Positions!$D:$D,$F30)) -> 0 | H30: =IF($B$3="","",SUMIFS(Positions!$P:$P,Positions!$A:$A,$B$3,Positions!$B:$B,H$21,Positions!$D:$D,$F30)) -> 0 | I30: =IF($B$3="","",SUMIFS(Positions!$P:$P,Positions!$A:$A,$B$3,Positions!$B:$B,I$21,Positions!$D:$D,$F30)) -> 0 | J30: =IF($B$3="","",SUMIFS(Positions!$P:$P,Positions!$A:$A,$B$3,Positions!$B:$B,J$21,Positions!$D:$D,$F30)) -> 0 | K30: =IF($B$3="","",SUMIFS(Positions!$P:$P,Positions!$A:$A,$B$3,Positions!$B:$B,K$21,Positions!$D:$D,$F30)) -> 0
F31: =Listes!C11 -> Crypto | G31: =IF($B$3="","",SUMIFS(Positions!$P:$P,Positions!$A:$A,$B$3,Positions!$D:$D,$F31)) -> 0 | H31: =IF($B$3="","",SUMIFS(Positions!$P:$P,Positions!$A:$A,$B$3,Positions!$B:$B,H$21,Positions!$D:$D,$F31)) -> 0 | I31: =IF($B$3="","",SUMIFS(Positions!$P:$P,Positions!$A:$A,$B$3,Positions!$B:$B,I$21,Positions!$D:$D,$F31)) -> 0 | J31: =IF($B$3="","",SUMIFS(Positions!$P:$P,Positions!$A:$A,$B$3,Positions!$B:$B,J$21,Positions!$D:$D,$F31)) -> 0 | K31: =IF($B$3="","",SUMIFS(Positions!$P:$P,Positions!$A:$A,$B$3,Positions!$B:$B,K$21,Positions!$D:$D,$F31)) -> 0
F32: =Listes!C12 -> Immobilier | G32: =IF($B$3="","",SUMIFS(Positions!$P:$P,Positions!$A:$A,$B$3,Positions!$D:$D,$F32)) -> 0 | H32: =IF($B$3="","",SUMIFS(Positions!$P:$P,Positions!$A:$A,$B$3,Positions!$B:$B,H$21,Positions!$D:$D,$F32)) -> 0 | I32: =IF($B$3="","",SUMIFS(Positions!$P:$P,Positions!$A:$A,$B$3,Positions!$B:$B,I$21,Positions!$D:$D,$F32)) -> 0 | J32: =IF($B$3="","",SUMIFS(Positions!$P:$P,Positions!$A:$A,$B$3,Positions!$B:$B,J$21,Positions!$D:$D,$F32)) -> 0 | K32: =IF($B$3="","",SUMIFS(Positions!$P:$P,Positions!$A:$A,$B$3,Positions!$B:$B,K$21,Positions!$D:$D,$F32)) -> 0
F33: =Listes!C13 -> SCI | G33: =IF($B$3="","",SUMIFS(Positions!$P:$P,Positions!$A:$A,$B$3,Positions!$D:$D,$F33)) -> 0 | H33: =IF($B$3="","",SUMIFS(Positions!$P:$P,Positions!$A:$A,$B$3,Positions!$B:$B,H$21,Positions!$D:$D,$F33)) -> 0 | I33: =IF($B$3="","",SUMIFS(Positions!$P:$P,Positions!$A:$A,$B$3,Positions!$B:$B,I$21,Positions!$D:$D,$F33)) -> 0 | J33: =IF($B$3="","",SUMIFS(Positions!$P:$P,Positions!$A:$A,$B$3,Positions!$B:$B,J$21,Positions!$D:$D,$F33)) -> 0 | K33: =IF($B$3="","",SUMIFS(Positions!$P:$P,Positions!$A:$A,$B$3,Positions!$B:$B,K$21,Positions!$D:$D,$F33)) -> 0
F34: =Listes!C14 -> Dette | G34: =IF($B$3="","",SUMIFS(Positions!$P:$P,Positions!$A:$A,$B$3,Positions!$D:$D,$F34)) -> 0 | H34: =IF($B$3="","",SUMIFS(Positions!$P:$P,Positions!$A:$A,$B$3,Positions!$B:$B,H$21,Positions!$D:$D,$F34)) -> 0 | I34: =IF($B$3="","",SUMIFS(Positions!$P:$P,Positions!$A:$A,$B$3,Positions!$B:$B,I$21,Positions!$D:$D,$F34)) -> 0 | J34: =IF($B$3="","",SUMIFS(Positions!$P:$P,Positions!$A:$A,$B$3,Positions!$B:$B,J$21,Positions!$D:$D,$F34)) -> 0 | K34: =IF($B$3="","",SUMIFS(Positions!$P:$P,Positions!$A:$A,$B$3,Positions!$B:$B,K$21,Positions!$D:$D,$F34)) -> 0
F35: =Listes!C15 -> Autre | G35: =IF($B$3="","",SUMIFS(Positions!$P:$P,Positions!$A:$A,$B$3,Positions!$D:$D,$F35)) -> 0 | H35: =IF($B$3="","",SUMIFS(Positions!$P:$P,Positions!$A:$A,$B$3,Positions!$B:$B,H$21,Positions!$D:$D,$F35)) -> 0 | I35: =IF($B$3="","",SUMIFS(Positions!$P:$P,Positions!$A:$A,$B$3,Positions!$B:$B,I$21,Positions!$D:$D,$F35)) -> 0 | J35: =IF($B$3="","",SUMIFS(Positions!$P:$P,Positions!$A:$A,$B$3,Positions!$B:$B,J$21,Positions!$D:$D,$F35)) -> 0 | K35: =IF($B$3="","",SUMIFS(Positions!$P:$P,Positions!$A:$A,$B$3,Positions!$B:$B,K$21,Positions!$D:$D,$F35)) -> 0
F36: Total | G36: =IF(SUM(G22:G35)=D11,SUM(G22:G35),"Erreur") -> 0 | H36: =IF(SUM(H22:H35)=D7,SUM(H22:H35),"Erreur") -> 0 | I36: =IF(SUM(I22:I35)=D8,SUM(I22:I35),"Erreur") -> 0 | J36: =IF(SUM(J22:J35)=D9,SUM(J22:J35),"Erreur") -> 0 | K36: =IF(SUM(K22:K35)=D10,SUM(K22:K35),"Erreur") -> 0
F38: Répartition mobilisable par liquidité (net)
F39: Liquidité | G39: Mobilisable (€) | H39: {=TRANSPOSE(Listes!A2:A5)} -> Paul | I39: Claire | J39: Léo | K39: Zoé
F40: =Listes!E2 -> J0–J1 | G40: =IF($B$3="","",SUMIFS(Positions!$T:$T,Positions!$A:$A,$B$3,Positions!$Q:$Q,F40)) -> 0 | H40: =IF($B$3="","",SUMIFS(Positions!$T:$T,Positions!$A:$A,$B$3,Positions!$B:$B,H$6,Positions!$Q:$Q,$F40)) -> 0 | I40: =IF($B$3="","",SUMIFS(Positions!$T:$T,Positions!$A:$A,$B$3,Positions!$B:$B,I$6,Positions!$Q:$Q,$F40)) -> 0 | J40: =IF($B$3="","",SUMIFS(Positions!$T:$T,Positions!$A:$A,$B$3,Positions!$B:$B,J$6,Positions!$Q:$Q,$F40)) -> 0 | K40: =IF($B$3="","",SUMIFS(Positions!$T:$T,Positions!$A:$A,$B$3,Positions!$B:$B,K$6,Positions!$Q:$Q,$F40)) -> 0
F41: =Listes!E3 -> J2–J7 | G41: =IF($B$3="","",SUMIFS(Positions!$T:$T,Positions!$A:$A,$B$3,Positions!$Q:$Q,F41)) -> 0 | H41: =IF($B$3="","",SUMIFS(Positions!$T:$T,Positions!$A:$A,$B$3,Positions!$B:$B,H$6,Positions!$Q:$Q,$F41)) -> 0 | I41: =IF($B$3="","",SUMIFS(Positions!$T:$T,Positions!$A:$A,$B$3,Positions!$B:$B,I$6,Positions!$Q:$Q,$F41)) -> 0 | J41: =IF($B$3="","",SUMIFS(Positions!$T:$T,Positions!$A:$A,$B$3,Positions!$B:$B,J$6,Positions!$Q:$Q,$F41)) -> 0 | K41: =IF($B$3="","",SUMIFS(Positions!$T:$T,Positions!$A:$A,$B$3,Positions!$B:$B,K$6,Positions!$Q:$Q,$F41)) -> 0
F42: =Listes!E4 -> J8–J30 | G42: =IF($B$3="","",SUMIFS(Positions!$T:$T,Positions!$A:$A,$B$3,Positions!$Q:$Q,F42)) -> 0 | H42: =IF($B$3="","",SUMIFS(Positions!$T:$T,Positions!$A:$A,$B$3,Positions!$B:$B,H$6,Positions!$Q:$Q,$F42)) -> 0 | I42: =IF($B$3="","",SUMIFS(Positions!$T:$T,Positions!$A:$A,$B$3,Positions!$B:$B,I$6,Positions!$Q:$Q,$F42)) -> 0 | J42: =IF($B$3="","",SUMIFS(Positions!$T:$T,Positions!$A:$A,$B$3,Positions!$B:$B,J$6,Positions!$Q:$Q,$F42)) -> 0 | K42: =IF($B$3="","",SUMIFS(Positions!$T:$T,Positions!$A:$A,$B$3,Positions!$B:$B,K$6,Positions!$Q:$Q,$F42)) -> 0
F43: =Listes!E5 -> 30J+ | G43: =IF($B$3="","",SUMIFS(Positions!$T:$T,Positions!$A:$A,$B$3,Positions!$Q:$Q,F43)) -> 0 | H43: =IF($B$3="","",SUMIFS(Positions!$T:$T,Positions!$A:$A,$B$3,Positions!$B:$B,H$6,Positions!$Q:$Q,$F43)) -> 0 | I43: =IF($B$3="","",SUMIFS(Positions!$T:$T,Positions!$A:$A,$B$3,Positions!$B:$B,I$6,Positions!$Q:$Q,$F43)) -> 0 | J43: =IF($B$3="","",SUMIFS(Positions!$T:$T,Positions!$A:$A,$B$3,Positions!$B:$B,J$6,Positions!$Q:$Q,$F43)) -> 0 | K43: =IF($B$3="","",SUMIFS(Positions!$T:$T,Positions!$A:$A,$B$3,Positions!$B:$B,K$6,Positions!$Q:$Q,$F43)) -> 0
...

Sheet TCD
A2: Entité (si indivision/SCI) | B2: (Tous)
A3: Date | B3: (Plusieurs éléments)
A5: Sum - Valeur nette attribuée (€) | E5: Catégorie
A6: Propriétaire | B6: Liquidité (délai) | C6: Établissement | D6: Enveloppe | E6: Total général
A7: Total général
